<?xml version='1.0'?>
<sdf version='1.6'>
  <model name="qev2">
  <!--static>true</static-->
    <link name='chassis'>
      <pose>0 0 .3 0 0 0</pose>
    <inertial>
        <mass>46</mass>
        <inertia>
          <ixx>3.5923125</ixx>
          <iyy>19.4891458333</iyy>
          <izz>20.0385583333</izz>
          <ixy>0</ixy>
          <ixz>0</ixz>
          <iyz>0</iyz>
        </inertia>
      </inertial>
      <collision name='collision'>
        <geometry>
	  <box>
	    <size>2.165 0.735 0.63</size>
	  </box>
	</geometry>
      </collision>

      <visual name='visual'>
        <geometry>
	  <box>
	    <size>2.165 0.735 0.63</size>
	  </box>
        </geometry>
      </visual>
    </link>

<!-- red = y, green = z, blue = x -->

    <link name='left_rear_wheel'>
      <pose>0.6 -0.6 0.1 0 1.5707 1.5707</pose>
      <inertial>
        <mass>3</mass>
        <inertia>
          <ixx>0.0262499475</ixx>
          <iyy>0.0262499475</iyy>
          <izz>0.040887015</izz>
          <ixy>0</ixy>
          <ixz>0</ixz>
          <iyz>0</iyz>
        </inertia>
      </inertial>
        <collision name='collision'>
          <geometry>
            <cylinder>
              <radius>.1651</radius>
                <length>.1524</length>
            </cylinder>
          </geometry>
        </collision>
        <visual name='visual'>
          <geometry>
            <cylinder>
              <radius>.1651</radius>
                <length>.1524</length>
            </cylinder>
          </geometry>
        </visual>
      </link>

      <joint type="revolute" name="joint_lr">
        <pose>0 0 0 0 1.5707 1.5707</pose>
	<parent>chassis</parent>
	<child>left_rear_wheel</child>
	<axis>
	  <xyz>1 0 0</xyz>
	<dynamics>
  
	<!--  <friction>0.01</friction>-->
	</dynamics>
        </axis>
      </joint>

    <link name='right_rear_wheel'>
      <pose>0.6 0.6 0.1 0 1.5707 1.5707</pose>
      <inertial>
        <mass>3</mass>
        <inertia>
          <ixx>0.0262499475</ixx>
          <iyy>0.0262499475</iyy>
          <izz>0.040887015</izz>
          <ixy>0</ixy>
          <ixz>0</ixz>
          <iyz>0</iyz>
        </inertia>
      </inertial>
        <collision name='collision'>
          <geometry>
            <cylinder>
              <radius>.1651</radius>
                <length>.1524</length>
            </cylinder>
          </geometry>
        </collision>
        <visual name='visual'>
          <geometry>
            <cylinder>
              <radius>.1651</radius>
                <length>.1524</length>
            </cylinder>
          </geometry>
        </visual>
     </link>

      <joint type="revolute" name="joint_rr">
      <pose>0 0 0 0 1.5707 1.5707</pose>
	<parent>chassis</parent>
	<child>right_rear_wheel</child>
	<axis>
	  <xyz>1 0 0</xyz>
	</axis>
	<dynamics>
	  	<!--  <friction>0.01</friction>-->
	</dynamics>
      </joint>

    <link name='left_front_wheel'>
      <pose>-0.6 -0.6 0.1 0 1.5707 1.5707</pose>
      <inertial>
        <mass>3</mass>
        <inertia>
          <ixx>0.0262499475</ixx>
          <iyy>0.0262499475</iyy>
          <izz>0.040887015</izz>
          <ixy>0</ixy>
          <ixz>0</ixz>
          <iyz>0</iyz>
        </inertia>
      </inertial>
        <collision name='collision'>
          <geometry>
            <cylinder>
              <radius>.1651</radius>
                <length>.1524</length>
            </cylinder>
          </geometry>
        </collision>
        <visual name='visual'>
          <geometry>
            <cylinder>
              <radius>.1651</radius>
                <length>.1524</length>
            </cylinder>
          </geometry>
        </visual>
     </link>

      <joint type="revolute" name="joint_lf">
      <pose>0 0 0 0 1.5707 1.5707</pose>
	<parent>chassis</parent>
	<child>left_front_wheel</child>
	<axis>
	  <xyz>1 0 0</xyz>
	</axis>
	<dynamics>
	  <!--  <friction>0.01</friction>-->
	</dynamics>
      </joint>

      <!-- <joint type="revolute" name="joint_lf_ackerman_steering">
      <pose>0 0 0 0 1.5707 1.5707</pose>
	<parent>chassis</parent>
	<child>left_front_wheel</child>
	<axis>
	  <xyz>0 1 0</xyz>
	</axis>
	<dynamics>
	  <friction>0.01</friction>
	</dynamics>
      </joint> -->

    <link name='right_front_wheel'>
      <pose>-0.6 0.6 0.1 0 1.5707 1.5707</pose>
      <inertial>
        <mass>3</mass>
        <inertia>
          <ixx>0.0262499475</ixx>
          <iyy>0.0262499475</iyy>
          <izz>0.040887015</izz>
          <ixy>0</ixy>
          <ixz>0</ixz>
          <iyz>0</iyz>
        </inertia>
      </inertial>
        <collision name='collision'>
          <geometry>
            <cylinder>
              <radius>.1651</radius>
                <length>.1524</length>
            </cylinder>
          </geometry>
        </collision>
        <visual name='visual'>
          <geometry>
            <cylinder>
              <radius>.1651</radius>
                <length>.1524</length>
            </cylinder>
          </geometry>
        </visual>
     </link>

      <joint type="revolute" name="joint_rf">
      <pose>0 0 0 0 1.5707 1.5707</pose>
	<parent>chassis</parent>
	<child>right_front_wheel</child>
	<axis>
	  <xyz>1 0 0</xyz>
	</axis>
	<dynamics>
	  	<!--  <friction>0.01</friction>-->
	</dynamics>
      </joint>

<!-- <joint type="revolute" name="joint_rf_ackerman_steering">
      <pose>0 0 0 0 1.5707 1.5707</pose>
	<parent>chassis</parent>
	<child>right_front_wheel</child>
	<axis>
	  <xyz>0 1 0</xyz>
	</axis>
	<dynamics>
	 	<friction>0.01</friction>
	</dynamics>
      </joint> -->


  </model>
</sdf>    


