<?xml version="1.0"?>
<sdf version="1.6">
  <model name="QEV2">
    <link name="chassis">
      <pose>0 0 0.3  0 0 0</pose>
      <inertial>
        <mass>46</mass>
        <inertia>
          <ixx>3.5923125</ixx>
          <iyy>19.4891458333</iyy>
          <izz>20.0385583333</izz>
          <ixy>0</ixy>
          <ixz>0</ixz>
          <iyz>0</iyz>
        </inertia>
      </inertial>
      <collision name="collision">
        <geometry>
          <box>
            <size>2.165 0.735 0.63</size>
          </box>
        </geometry>
      </collision>
      <visual name="visual">
        <geometry>
          <box>
            <size>2.165 0.735 0.63</size>
          </box>
        </geometry>
      </visual>
    </link>
    <link name="wheel_front_left">
      <pose>0.6 0.6 0.1 -1.5707963267948966 -0.08726646259971647 0</pose>
      <inertial>
        <mass>3</mass>
        <inertia>
          <ixx>0.0262499475</ixx>
          <iyy>0.0262499475</iyy>
          <izz>0.040887015</izz>
          <ixy>0</ixy>
          <ixz>0</ixz>
          <iyz>0</iyz>
        </inertia>
      </inertial>
      <collision name="collision">
        <geometry>
          <cylinder>
            <radius>.1651</radius>
            <length>.1524</length>
          </cylinder>
        </geometry>
      </collision>
      <visual name="visual">
        <geometry>
          <cylinder>
            <radius>.1651</radius>
            <length>.1524</length>
          </cylinder>
        </geometry>
      </visual>
    </link>
    <joint name="wheel_front_left_steer_spin" type="universal">
      <parent>chassis</parent>
      <child>wheel_front_left</child>
      <axis>
        <xyz>0 -1 0</xyz>
        <limit>
          <lower>-0.6108652381980153</lower>
          <upper>0.6108652381980153</upper>
        </limit>
      </axis>
      <axis2>
        <xyz>0 0 1</xyz>
      </axis2>
    </joint>
    <link name="wheel_front_right">
      <pose>0.6 -0.6 0.1 -1.5707963267948966 -0.08726646259971647 0</pose>
      <inertial>
        <mass>3</mass>
        <inertia>
          <ixx>0.0262499475</ixx>
          <iyy>0.0262499475</iyy>
          <izz>0.040887015</izz>
          <ixy>0</ixy>
          <ixz>0</ixz>
          <iyz>0</iyz>
        </inertia>
      </inertial>
      <collision name="collision">
        <geometry>
          <cylinder>
            <radius>.1651</radius>
            <length>.1524</length>
          </cylinder>
        </geometry>
      </collision>
      <visual name="visual">
        <geometry>
          <cylinder>
            <radius>.1651</radius>
            <length>.1524</length>
          </cylinder>
        </geometry>
      </visual>
    </link>
    <joint name="wheel_front_right_steer_spin" type="universal">
      <parent>chassis</parent>
      <child>wheel_front_right</child>
      <axis>
        <xyz>0 -1 0</xyz>
        <limit>
          <lower>-0.6108652381980153</lower>
          <upper>0.6108652381980153</upper>
        </limit>
      </axis>
      <axis2>
        <xyz>0 0 1</xyz>
      </axis2>
    </joint>
    <link name="wheel_rear_left">
      <pose>-0.6 0.6 0.1 -1.5707963267948966 0 0</pose>
      <inertial>
        <mass>3</mass>
        <inertia>
          <ixx>0.0262499475</ixx>
          <iyy>0.0262499475</iyy>
          <izz>0.040887015</izz>
          <ixy>0</ixy>
          <ixz>0</ixz>
          <iyz>0</iyz>
        </inertia>
      </inertial>
      <collision name="collision">
        <geometry>
          <cylinder>
            <radius>.1651</radius>
            <length>.1524</length>
          </cylinder>
        </geometry>
      </collision>
      <visual name="visual">
        <geometry>
          <cylinder>
            <radius>.1651</radius>
            <length>.1524</length>
          </cylinder>
        </geometry>
      </visual>
    </link>
    <joint name="wheel_rear_left_spin" type="revolute">
      <parent>chassis</parent>
      <child>wheel_rear_left</child>
      <axis>
        <xyz>0 0 1</xyz>
      </axis>
    </joint>
    <link name="wheel_rear_right">
      <pose>-0.6 -0.6 0.1 -1.5707963267948966 0 0</pose>
      <inertial>
        <mass>3</mass>
        <inertia>
          <ixx>0.0262499475</ixx>
          <iyy>0.0262499475</iyy>
          <izz>0.040887015</izz>
          <ixy>0</ixy>
          <ixz>0</ixz>
          <iyz>0</iyz>
        </inertia>
      </inertial>
      <collision name="collision">
        <geometry>
          <cylinder>
            <radius>.1651</radius>
            <length>.1524</length>
          </cylinder>
        </geometry>
      </collision>
      <visual name="visual">
        <geometry>
          <cylinder>
            <radius>.1651</radius>
            <length>.1524</length>
          </cylinder>
        </geometry>
      </visual>
    </link>
    <joint name="wheel_rear_right_spin" type="revolute">
      <parent>chassis</parent>
      <child>wheel_rear_right</child>
      <axis>
        <xyz>0 0 1</xyz>
      </axis>
    </joint>
    <!-- Add lidar to QEV2 -->
    <include>
      <uri>model://horizon_lidar</uri>
      <pose>1.1 0 0.67 0 0 0</pose>
    </include>
    <joint name="horizon_lidar_joint" type="fixed">
      <child>horizon_lidar::base</child>
      <parent>chassis</parent>
    </joint>
    <!-- Add (stereo) camera to QEV2 -->
    <include>
      <uri>model://zed_camera</uri>
      <pose>-0.4 0 1.3 0 0 0</pose>
    </include>
    <joint name="zed_camera_joint" type="fixed">
      <child>zed_camera::base</child>
      <parent>chassis</parent>
    </joint>
  </model>
</sdf>
