<?xml version="1.0"?>

<robot xmlns:xacro="http://ros.org/wiki/xacro" name="husky_wheel">

	<xacro:macro name="qev2_wheel_front" params="wheel_prefix *joint_pose">

		<!-- Supsension link -->
		<link name="front_${wheel_prefix}_susp_link">
			<inertial>
				<mass value="3" />
				<origin xyz="0 0 0" />
				<inertia  ixx="0.0208333333333333" ixy="0" ixz="0" iyy="0.0208333333333333" iyz="0" izz="0.0208333333333333" />
			</inertial>
			<visual>
				<origin xyz="0 0 0" rpy="${M_PI/2} 0 0" />
				<geometry>
					<box size="0.1 0.1 0.1" />
				</geometry>
			</visual>
			<collision>
				<origin xyz="0 0 0" rpy="${M_PI/2} 0 0" />
				<geometry>
					<box size="0.1 0.1 0.1" />
				</geometry>
			</collision>
		</link>

		<!-- Gazebo reference for suspension link -->
		<gazebo reference="front_${wheel_prefix}_susp_link">
			<material>Gazebo/Green</material>
		</gazebo>

		<!-- Wheel link -->
		<link name="front_${wheel_prefix}_wheel_link">
			<inertial>
				<mass value="3" />
				<origin xyz="0 0 0" />
				<inertia  ixx="0.0262499475" ixy="0" ixz="0" iyy="0.0262499475" iyz="0" izz="0.040887015" />
			</inertial>
			<visual>
				<origin xyz="0 0 0" rpy="${M_PI/2} 0 0" />
				<geometry>
					<cylinder length="${wheel_length}" radius="${wheel_radius}" />
				</geometry>
			</visual>
			<collision>
				<origin xyz="0 0 0" rpy="${M_PI/2} 0 0" />
				<geometry>
					<cylinder length="${wheel_length}" radius="${wheel_radius}" />
				</geometry>
			</collision>
		</link>

		<!-- Gazebo reference for wheel link -->
		<gazebo reference="front_${wheel_prefix}_wheel_link">
			<mu1 value="1.0"/>
			<mu2 value="1.0"/>
			<kp value="10000000.0" />
			<kd value="1.0" />
			<fdir1 value="1 0 0"/>
			<material>Gazebo/Black</material>
		</gazebo>

		<!-- Joint connecting chassis (base_link) with suspension -->
		<joint name="front_${wheel_prefix}_susp_joint" type="prismatic">
			<parent link="base_link"/>
			<child link="front_${wheel_prefix}_susp_link"/>
			<xacro:insert_block name="joint_pose"/>
			<axis xyz="0 0 -1" rpy="0 0 0" />
			<limit effort="1000.0" lower="-0.075" upper="0.075" velocity="0.5"/>
			<dynamics damping="700" spring_stiffness="1500" spring_reference="0.001" />
			<physics>
				<ode implicit_spring_damper="1" />
			</physics>
		</joint>

		<!-- Joint connecting suspension with wheel -->
		<joint name="front_${wheel_prefix}_wheel_joint" type="continuous">
			<parent link="front_${wheel_prefix}_susp_link"/>
			<child link="front_${wheel_prefix}_wheel_link"/>
			<axis xyz="0 1 0" rpy="0 0 0" />
			<!-- <limit effort="-1" velocity="-1"/>
			<physics>
				<ode>
					<limit cfm="0" erp="0.2" />
					<suspension cfm="0" erp="0.2" />
				</ode>
			</physics> -->
		</joint>

		<transmission name="front_${wheel_prefix}_wheel_trans" type="SimpleTransmission">
			<type>transmission_interface/SimpleTransmission</type>
			<actuator name="front_${wheel_prefix}_wheel_motor">
				<mechanicalReduction>1</mechanicalReduction>
			</actuator>
			<joint name="front_${wheel_prefix}_wheel_joint">
				<hardwareInterface>hardware_interface/VelocityJointInterface</hardwareInterface>
			</joint>
		</transmission>

	</xacro:macro>
</robot>
