"<?xml version="1.0" encoding="utf-8"?><!-- ===================================================================================
 --><!-- |    This document was autogenerated by xacro from /home/philly/catkin_ws/src/qut/qutms_autonomous/urdf/qev2_base_gazebo.xacro\
 | --><!-- |    EDITING THIS FILE BY HAND IS NOT RECOMMENDED              
                 | --><!-- ===================================================================================
 -->
<robot name="qev2">  <!-- Chassis -->
  <link name="base_link">
    <visual>
      <origin rpy="0 0 0" xyz="0 0 0.4"/>
      <geometry>
        <box size="2.165 0.735 0.63"/>
      </geometry>
    </visual>
    <collision>
      <origin rpy="0 0 0" xyz="0 0 0.4"/>
      <geometry>
        <box size="2.165 0.735 0.63"/>
      </geometry>
    </collision>
  </link>  <!-- Interial link stores the robot's inertial information --> \
  <link name="inertial_link">
    <inertial>
      <origin rpy="0 0 0" xyz="0 0 0.4"/>
      <mass value="46"/>
      <inertia ixx="3.5923125" ixy="0" ixz="0" iyy="19.4891458333" iyz="0" izz="20.0385583333"/>
    </inertial>
  </link>
  <joint name="inertial_joint" type="fixed">
    <origin rpy="0 0 0" xyz="0 0 0"/>
    <parent link="base_link"/>
    <child link="inertial_link" />
  </joint>  <!-- QEV2 wheel macros -->  <!-- Supsension link -->
  <link\ name="front_left_susp_link">
    <inertial>
      <mass value="3"/>
      <origin xyz="0 0 0"/>
      <inertia ixx="0.0208333333333333" ixy="0" ixz="0" iyy="0.0208333333333333" iyz="0" izz="0.0208333333333333"/>
    </inertial>
    <visual>
      <origin rpy="1.57079632679 0 0" xyz="0 0 0"/>
      <geometry>
        <box size="0.1 0.1 0.1"/>
      </geometry>
    </visual>
    <collision>
      <origin rpy="1.57079632679 0 0" xyz="0 0 0"/>
      <geometry>
        <box size="0.1 0.1 0.1"/>
      </geometry>
    </collision>
  </link>  <!-- Gazebo reference for suspension link -->
  <gazebo reference="front_left_susp_link">
    <material>Gazebo/Green</material>
  </gazebo>  <!-- Wheel link -->
  <link name="front_left_wheel_link"> \
    <inertial>
      <mass value="3"/>
      <origin xyz="0 0 0"/>
      <inertia ixx="0.0262499475" ixy="0" ixz="0" iyy="0.0262499475" iyz="0" izz="0.040887015"/>
    </inertial>
    <visual>
      <origin rpy="1.57079632679\0 0" xyz="0 0 0"/>
      <geometry>
        <cylinder length="0.1524" radius="0.1651"/>
      </geometry>
    </visual>
    <collision>
      <origin rpy="1.57079632679 0 0" xyz="0 0 0"/>
      <geometry>
        <cylinder length="0.1524" radius="0.1651"/>
      </geometry>
    </collision>
  </link> \
   <!-- Gazebo reference for wheel link -->
  <gazebo reference="front_left_wheel_link">
    <mu1 value="1.0"/>
    <mu2 value="1.0"/>
    <kp value="10000000.0" />
    <kd value="1.0"/>
    <fdir1 value="1 0 0"/>
    <material>Gazebo/Black</material>
  </gazebo>  <!-- Joint connecting chassis (base_link) with suspension -->
  <joint name="front_left_susp_joint" type="prismatic">
    <parent link="base_link"/>
    <child link="front_left_susp_link"/>
    <origin rpy="0 0 0" xyz="0.6 0.6 0.1"/>
    <axis rpy="0 0 0" xyz="0 0 -1"/>
    <limit effort="1000.0" lower="-0.075" upper="0.075" velocity="0.5"/>
    <dynamics damping="700" spring_reference="0.001" spring_stiffness="1500"/>
    <physics>
      <ode implicit_spring_damper="1"/>
    </physics>
  </joint>  <!-- Joint\
 connecting suspension with wheel -->
  <joint name="front_left_wheel_joint" type="continuous">
    <parent link="front_left_susp_link"/>
    <child\ link="front_left_wheel_link"/>
    <!-- <xacro:insert_block name="joint_pose" /> -->
    <axis rpy="0 0 0" xyz="0 1 0"/>
    <limit effort="-1" velocity="-1"/>
    <physics>
      <ode>
        <limit cfm="0" erp="0.2"/>
        <suspension cfm="0" erp="0.2"/>
      </ode>
    </physics>
  </joint>
  <transmission name="front_left_wheel_trans" type="SimpleTransmission">
    <type>transmission_interface/SimpleTransmission</type>
    <actuator name="
  front_left_wheel_motor">
      <mechanicalReduction>1</mechanicalReduction>
    </actuator>
    <joint name="front_left_wheel_joint">
      <hardwareInterface>hardware_interface/VelocityJointInterface</hardwareInterface>
    </joint>
  </transmission>  <!-- Supsension link -->
  <link name="front_right_susp_link">
    <inertial>
      <mass value="3"/>
      <origin xyz="0 0 0"/>
      <inertia ixx="0.0208333333333333" ixy="0" ixz="0" iyy="0.0208333333333333" iyz="0" izz="0.0208333333333333"/>
    </inertial>
    <visual>
      <origin\ rpy="1.57079632679 0 0" xyz="0 0 0"/>
      <geometry>
        <box size="
  0.1 0.1 0.1"/>
      </geometry>
    </visual>
    <collision>
      <origin\ rpy="1.57079632679 0 0" xyz="0 0 0"/>
      <geometry>
        <box size="
  0.1 0.1 0.1"/>
      </geometry>
    </collision>
  </link>  <!-- Gazebo reference\
 for suspension link -->
  <gazebo reference="front_right_susp_link">
    <material>Gazebo/Green</material>
  </gazebo>  <!-- Wheel link -->
  <link name="front_right_wheel_link">
    <inertial>
      <mass value="3"/>
      <origin xyz="0 0 0"/>
      <inertia ixx="0.0262499475" ixy="0" ixz="0" iyy="0.0262499475" iyz="
  0" izz="0.040887015"/>
    </inertial>
    <visual>
      <origin rpy="1.57079632679\
 0 0" xyz="0 0 0"/>
      <geometry>
        <cylinder length="0.1524" radius="
  0.1651"/>
      </geometry>
    </visual>
    <collision>
      <origin rpy="
  1.57079632679 0 0" xyz="0 0 0"/>
      <geometry>
        <cylinder length="
  0.1524" radius="0.1651"/>
      </geometry>
    </collision>
  </link> \
   <!-- Gazebo reference for wheel link -->
  <gazebo reference="front_right_wheel_link">
    <mu1 value="1.0"/>
    <mu2 value="1.0"/>
    <kp value="10000000.0" />
    <kd value="1.0"/>
    <fdir1 value="1 0 0"/>
    <material>Gazebo/Black</material>
  </gazebo>  <!-- Joint connecting chassis (base_link) with suspension -->
  <joint name="front_right_susp_joint" type="prismatic">
    <parent link="
  base_link"/>
    <child link="front_right_susp_link"/>
    <origin rpy="0\
 0 0" xyz="0.6 -0.6 0.1"/>
    <axis rpy="0 0 0" xyz="0 0 -1"/>
    <limit\ effort="1000.0" lower="-0.075" upper="0.075" velocity="0.5"/>
    <dynamics\ damping="700" spring_reference="0.001" spring_stiffness="1500"/>
    <physics>
      <ode implicit_spring_damper="1"/>
    </physics>
  </joint>  <!-- Joint\
 connecting suspension with wheel -->
  <joint name="front_right_wheel_joint" type="continuous">
    <parent link="front_right_susp_link"/>
    <child\ link="front_right_wheel_link"/>
    <!-- <xacro:insert_block name="joint_pose" /> -->
    <axis rpy="0 0 0" xyz="0 1 0"/>
    <limit effort="-1" velocity="
  -1"/>
    <physics>
      <ode>
        <limit cfm="0" erp="0.2"/>
        <suspension cfm="0" erp="0.2"/>
      </ode>
    </physics>
  </joint>
  <transmission name="front_right_wheel_trans" type="SimpleTransmission">
    <type>transmission_interface/SimpleTransmission</type>
    <actuator name="
  front_right_wheel_motor">
      <mechanicalReduction>1</mechanicalReduction>
    </actuator>
    <joint name="front_right_wheel_joint">
      <hardwareInterface>hardware_interface/VelocityJointInterface</hardwareInterface>
    </joint>
  </transmission>  <!-- Supsension link -->
  <link name="rear_left_susp_link">
    <inertial>
      <mass value="3"/>
      <origin xyz="0 0 0"/>
      <inertia ixx="0.0208333333333333" ixy="0" ixz="0" iyy="0.0208333333333333" iyz="0" izz="0.0208333333333333"/>
    </inertial>
    <visual>
      <origin\ rpy="1.57079632679 0 0" xyz="0 0 0"/>
      <geometry>
        <box size="
  0.1 0.1 0.1"/>
      </geometry>
    </visual>
    <collision>
      <origin\ rpy="1.57079632679 0 0" xyz="0 0 0"/>
      <geometry>
        <box size="
  0.1 0.1 0.1"/>
      </geometry>
    </collision>
  </link>  <!-- Gazebo reference\
 for suspension link -->
  <gazebo reference="rear_left_susp_link">
    <material>Gazebo/Green</material>
  </gazebo>  <!-- Wheel link -->
  <link name="rear_left_wheel_link">
    <inertial>
      <mass value="3"/>
      <origin xyz="0 0 0"/>
      <inertia\ ixx="0.0262499475" ixy="0" ixz="0" iyy="0.0262499475" iyz="0" izz="
  0.040887015"/>
    </inertial>
    <visual>
      <origin rpy="1.57079632679\
 0 0" xyz="0 0 0"/>
      <geometry>
        <cylinder length="0.1524" radius="
  0.1651"/>
      </geometry>
    </visual>
    <collision>
      <origin rpy="
  1.57079632679 0 0" xyz="0 0 0"/>
      <geometry>
        <cylinder length="
  0.1524" radius="0.1651"/>
      </geometry>
    </collision>
  </link> \
   <!-- Gazebo reference for wheel link -->
  <gazebo reference="rear_left_wheel_link">
    <mu1 value="1.0"/>
    <mu2 value="1.0"/>
    <kp value="10000000.0" />
    <kd value="1.0"/>
    <fdir1 value="1 0 0"/>
    <material>Gazebo/Black</material>
  </gazebo>  <!-- Joint connecting chassis (base_link) with suspension -->
  <joint name="rear_left_susp_joint" type="prismatic">
    <parent link="
  base_link"/>
    <child link="rear_left_susp_link"/>
    <origin rpy="0 0\
 0" xyz="-0.6 0.6 0.1"/>
    <axis rpy="0 0 0" xyz="0 0 -1"/>
    <limit\ effort="1000.0" lower="-0.075" upper="0.075" velocity="0.5"/>
    <dynamics\ damping="700" spring_reference="0.001" spring_stiffness="1500"/>
    <physics>
      <ode implicit_spring_damper="1"/>
    </physics>
  </joint>  <!-- Joint\
 connecting suspension with wheel -->
  <joint name="rear_left_wheel_joint" type="continuous">
    <parent link="rear_left_susp_link"/>
    <child link="
  rear_left_wheel_link"/>
    <!-- <xacro:insert_block name="joint_pose"/> -->
    <axis rpy="0 0 0" xyz="0 1 0"/>
    <limit effort="-1" velocity="-1" />
    <physics>
      <ode>
        <limit cfm="0" erp="0.2"/>
        <suspension cfm="0" erp="0.2"/>
      </ode>
    </physics>
  </joint>
  <!-- Transmission -->
  <transmission name="rear_left_wheel_trans" type="
  SimpleTransmission">
    <type>transmission_interface/SimpleTransmission</type>
    <actuator name="rear_left_wheel_motor">
      <mechanicalReduction>1</mechanicalReduction>
    </actuator>
    <joint name="rear_left_wheel_joint">
      <hardwareInterface>hardware_interface/VelocityJointInterface</hardwareInterface>
    </joint>
  </transmission>  <!-- Supsension link -->
  <link name="rear_right_susp_link">
    <inertial>
      <mass value="3"/>
      <origin xyz="0 0 0"/>
      <inertia ixx="0.0208333333333333" ixy="0" ixz="0" iyy="0.0208333333333333" iyz="0" izz="0.0208333333333333"/>
    </inertial>
    <visual>
      <origin\ rpy="1.57079632679 0 0" xyz="0 0 0"/>
      <geometry>
        <box size="
  0.1 0.1 0.1"/>
      </geometry>
    </visual>
    <collision>
      <origin\ rpy="1.57079632679 0 0" xyz="0 0 0"/>
      <geometry>
        <box size="
  0.1 0.1 0.1"/>
      </geometry>
    </collision>
  </link>  <!-- Gazebo reference\
 for suspension link -->
  <gazebo reference="rear_right_susp_link">
    <material>Gazebo/Green</material>
  </gazebo>  <!-- Wheel link -->
  <link name="rear_right_wheel_link"> \
    <inertial>
      <mass value="3"/>
      <origin xyz="0 0 0"/>
      <inertia ixx="0.0262499475" ixy="0" ixz="0" iyy="0.0262499475" iyz="
  0" izz="0.040887015"/>
    </inertial>
    <visual>
      <origin rpy="1.57079632679\
 0 0" xyz="0 0 0"/>
      <geometry>
        <cylinder length="0.1524" radius="
  0.1651"/>
      </geometry>
    </visual>
    <collision>
      <origin rpy="
  1.57079632679 0 0" xyz="0 0 0"/>
      <geometry>
        <cylinder length="
  0.1524" radius="0.1651"/>
      </geometry>
    </collision>
  </link> \
   <!-- Gazebo reference for wheel link -->
  <gazebo reference="rear_right_wheel_link">
    <mu1 value="1.0"/>
    <mu2 value="1.0"/>
    <kp value="10000000.0" />
    <kd value="1.0"/>
    <fdir1 value="1 0 0"/>
    <material>Gazebo/Black</material>
  </gazebo>  <!-- Joint connecting chassis (base_link) with suspension -->
  <joint name="rear_right_susp_joint" type="prismatic">
    <parent link="
  base_link"/>
    <child link="rear_right_susp_link"/>
    <origin rpy="0 0\
 0" xyz="-0.6 -0.6 0.1"/>
    <axis rpy="0 0 0" xyz="0 0 -1"/>
    <limit\ effort="1000.0" lower="-0.075" upper="0.075" velocity="0.5"/>
    <dynamics\ damping="700" spring_reference="0.001" spring_stiffness="1500"/>
    <physics>
      <ode implicit_spring_damper="1"/>
    </physics>
  </joint>  <!-- Joint\
 connecting suspension with wheel -->
  <joint name="rear_right_wheel_joint" type="continuous">
    <parent link="rear_right_susp_link"/>
    <child\ link="rear_right_wheel_link"/>
    <!-- <xacro:insert_block name="joint_pose" /> -->
    <axis rpy="0 0 0" xyz="0 1 0"/>
    <limit effort="-1" velocity="
  -1"/>
    <physics>
      <ode>
        <limit cfm="0" erp="0.2"/>
        <suspension cfm="0" erp="0.2"/>
      </ode>
    </physics>
  </joint>
  <!-- Transmission -->
  <transmission name="rear_right_wheel_trans" type="
  SimpleTransmission">
    <type>transmission_interface/SimpleTransmission</type>
    <actuator name="rear_right_wheel_motor">
      <mechanicalReduction>1</mechanicalReduction>
    </actuator>
    <joint name="rear_right_wheel_joint">
      <hardwareInterface>hardware_interface/VelocityJointInterface</hardwareInterface>
    </joint>
  </transmission>
  <gazebo>
    <plugin filename="libgazebo_ros_control.so" name="gazebo_ros_control">
      <robotNamespace>qev2</robotNamespace>
    </plugin>
  </gazebo>
  <gazebo reference="base_link">
    <material>Gazebo/Grey</material>
  </gazebo>  <!-- === Optional sensors - called by macros defined above === -->
</robot>"